+++
title = "C#中的throw和throw ex的区别"
slug = "C#中的throw和throw ex的区别"
date = "2023-09-07T17:57:58+08:00"
tags = [ "exception", ".net", "csharp",]
thumbnail = "/images/.net.256x256.png"
featureImage = "/images/.net.256x256.png"
+++


## 摘要

本教程将介绍C#中的throw和throw ex的区别。我们将讨论这两者之间的区别，并提供示例代码来说明它们的使用方法和效果。

## throw和throw ex的区别

- 使用throw语句时，异常的堆栈跟踪将被保留，即异常的堆栈跟踪包括了异常抛出的位置以及所有调用此方法的上级方法的信息。

- 使用throw ex语句时，异常的堆栈跟踪将被重置。只有当前方法抛出的异常信息会被保留，上级方法的信息不会包含在异常堆栈跟踪中。

## 示例代码

下面的示例代码演示了throw和throw ex的区别：

```csharp
static void Main(string[] args)
{
    try
    {
        Method1();
    }
    catch (Exception ex)
    {
        Console.WriteLine("Using throw:");
        Console.WriteLine(ex.StackTrace);
    }

    try
    {
        Method2();
    }
    catch (Exception ex)
    {
        Console.WriteLine("Using throw ex:");
        Console.WriteLine(ex.StackTrace);
    }

    Console.ReadKey();
}

static void Method1()
{
    try
    {
        throw new Exception("Exception in Method1");
    }
    catch (Exception ex)
    {
        throw;
    }
}

static void Method2()
{
    try
    {
        throw new Exception("Exception in Method2");
    }
    catch (Exception ex)
    {
        throw ex;
    }
}
```

输出结果如下：

```plaintext
Using throw:
   at Program.Method1() in Program


